Workbook

Sheet Introduction
A1: Introduction - Levelized Cost of Hydrogen (LCOH)
A4: Overview
A5: This workbook evaluates the Levelized Cost of Hydrogen (LCOH) for two PV-integrated hydrogen configurations serving an industrial coffee roasting application: Case 1 (30 bar low-pressure storage) and Case 2 (300 bar high-pressure storage). Technical and operational inputs originate from MATLAB/Simulink simulations and MILP optimization results. Annualized cost calculations and one-at-a-time and two-parameter sensitivity analyses are provided.
A6: Agora Energiewende (2023)
A7: Silva et.al. (2024)
A9: Workbook Navigation
A10: Economic Assumptions | D10: Technical and economic assumptions
A11: Case Inputs | D11: Input data from Optimization results of the System. Case 1 represents low-pressure storage of hydrogen at 30 bar and Case 2 represents high-pressure storage of hydrogen at 300 bar.
A12: Annualized Costs | D12: Calculation of equivalent annual costs of system components, including annualized capital expenditures (CAPEX) and operating expenditures (OPEX)
A13: LCOH | D13: Cost calculations and LCOH calculations
A14: OAT-Sensitivity | D14: One-at-a-time (OAT) sensitivity analysis with ±20 % variation in base value; results interpreted in Tornado chart
A15: OAT Scenario Curves | D15: One-at-a-Time (OAT) sensitivity analysis results, illustrating the impact of individual parameter variations on LCOH across different system scenarios
A16: Two-parameters sensitivity | D16: Evaluates the combined impact of variations in electrolyzer CAPEX and hydrogen storage costs on LCOH across case 1 and 2 configurations
B44: Figure 1: Schematic diagram of integrated simulation and optimization framework used in the project for the input data
B64: Figure 2: LCOH calculation formula used for economic assessment

Sheet Economic Assumptions
A1: Technical and Economic Assumptions
A3: Category | B3: Parameter | C3: Unit | D3: Base value | E3: Source / note
A4: General | B4: Discount rate | C4: % | D4: 0.06 | E4: Assumption
A5: General | B5: Project lifetime | C5: years | D5: 20 | E5: Assumption
A7: PV | B7: PV system CAPEX | C7: € | D7: =D10*D11*D27 -> 60000 | E7: Base value for 60kWp, 1000€ per kWp, Source: https://iea-pvps.org/national_survey/nsr-austria-2024/
A8: PV | B8: PV lifetime | C8: years | D8: 25 | E8: Assumption
A9: PV | B9: PV O&M rate | C9: % of CAPEX/yr | D9: 0.05 | E9: https://www.frontiersin.org/journals/energy-research/articles/10.3389/fenrg.2024.1380543/full
A10: PV | B10: Installed PV capacity | C10: kWp | D10: 60 | E10: array size: 190 × 320 W = 60 kWp
A11: PV | B11: PV CAPEX rate | C11: €/kWp | D11: 1000 | E11: IEA PVPS Austria survey
A13: Electrolyzer | B13: Electrolyzer CAPEX | C13: € | D13: 60000 | E13: https://h2-batarow.com/en/electrolyzer/ely-22
A14: Electrolyzer | B14: Electrolyzer system lifetime | C14: years | D14: 20 | E14: Assumption
A15: Electrolyzer | B15: Electrolyzer O&M rate | C15: % of CAPEX/yr | D15: 0.02 | E15: https://www.frontiersin.org/journals/energy-research/articles/10.3389/fenrg.2024.1380543/full
A16: Electrolyzer | B16: Stack replacement share | C16: % of ELY CAPEX | D16: 0.25 | E16: https://www.frontiersin.org/journals/energy-research/articles/10.3389/fenrg.2024.1380543/full
A17: Electrolyzer | B17: Stack durability | C17: full-load hours | D17: 60000 | E17: https://www.frontiersin.org/journals/energy-research/articles/10.3389/fenrg.2024.1380543/full
A19: Compressor | B19: Compressor CAPEX | C19: € | D19: 10000 | E19: https://h2-batarow.com/en/compressor
A20: Compressor | B20: Compressor lifetime | C20: years | D20: 15 | E20: Assumption
A21: Compressor | B21: Compressor O&M rate | C21: % of CAPEX/yr | D21: 0.04 | E21: https://www.frontiersin.org/journals/energy-research/articles/10.3389/fenrg.2024.1380543/full
... A32: Revenue | B32: Feed-in tariff | C32: €/kWh | D32: 0.045 | E32: Assumption

Sheet Case Inputs
A1: Optimization Case Inputs
A3: KPI | B3: Unit | C3: Case 1 | D3: Case 2 | G3: Notes
A4: Case description | B4: - | C4: LP storage, demand-matching | D4: HP storage, demand-matching | G4: Optimization cases
A5: Annual H₂ demand | B5: kg/yr | C5: 738.4 | D5: 738.4 | G5: Roaster demand
A6: Annual H₂ production | B6: kg/yr | C6: 738.4 | D6: 738.4 | G6: Optimization summary
A7: PV to electrolyzer | B7: kWh/yr | C7: 12990.855 | D7: 13056.278 | G7: Optimization summary
A8: Total grid electricity | B8: kWh/yr | C8: 30640 | D8: 30988.496 | G8: ELY + compressor + site; Optimization summary
A9: PV exported | B9: kWh/yr | C9: 61558.93 | D9: 61145.059 | G9: Optimization summary
A10: Total grid electricity cost | B10: €/yr | C10: 2821.31 | D10: 1309.66 | G10: ELY + compressor + site grid cost; Optimization summary
A11: Compressor energy | B11: kWh/yr | C11: 0 | D11: 745.78 | G11: Case 1 = 0
A12: LP storage capacity | B12: kg H₂ | C12: 6.96 | D12: 0 | G12: Optimization summary
A13: HP storage capacity | B13: kg H₂ | C13: 0 | D13: 7.68 | G13: Optimization summary
A14: LP internal volume | B14: m³ | C14: 2.84 | D14: 0 | G14: Optimization summary
A15: HP internal volume | B15: m³ | C15: 0 | D15: 0.33 | G15: Optimization summary
A16: Reported storage investment | B16: € | C16: 6967.35 | D16: 5254.77 | G16: Cross-check only; cost sheet recalculates CAPEX
A17: H₂ supplied to roaster | B17: kg/yr | C17: 738.4 | D17: 738.4
A18: Annual H₂ surplus | B18: kg/yr | C18: 0 | D18: 0 | G18: Production minus demand
A19: Grid to electrolyzer | B19: kWh/yr | C19: 28003.76 | D19: 28011.02 | G19: Optimization summary
A20: Grid to compressor | B20: kWh/yr | C20: 0 | D20: 321.86 | G20: Case 1 = 0
A21: Grid to site loads | B21: kWh/yr | C21: 2636.47 | D21: 2627.51 | G21: Optimization summary
A22: Grid cost – electrolyzer | B22: €/yr | C22: 2505.73 | D22: 2454.29 | G22: Optimization summary
A23: Grid cost – compressor | B23: €/yr | C23: 0 | D23: 30.69 | G23: Case 1 = 0
A24: Grid cost – site loads | B24: €/yr | C24: 315.57 | D24: 314.41 | G24: Optimization summary
A25: PV to compressor | B25: kWh/yr | C25: 0 | D25: 423.91 | G25: Case 1 = 0
A26: PV to site loads | B26: kWh/yr | C26: 7040.52 | D26: 7049.48 | G26: Optimization summary
A27: Feed-in revenue | B27: €/yr | C27: 3077.94 | D27: 3056.94 | G27: Calculated from PV export × base tariff
A28: Electrolyzer full-load hours | B28: h/yr | C28: =(C6*'Economic Assumptions'!D29)/10 -> 4099.5968 | D28: =(D6*'Economic Assumptions'!D29)/10 -> 4099.5968 | G28: = (Annual H2 * SEC of electrolyzer)/Power of Electrolyzer (10kW)
A29: Gross annual system cost | B29: €/yr | C29: ='Annualized Costs'!B21 -> 18661.926 | D29: ='Annualized Costs'!C21 -> 18413.872 | G29: Calculated in Annualized Costs
A30: Net annual system cost | B30: €/yr | C30: ='Annualized Costs'!B22 -> 15583.986 | D30: ='Annualized Costs'!C22 -> 15356.932 | G30: Gross cost less feed-in revenue

Sheet Annualized Costs
A1: Annualized Cost Calculation – Gross and Net of Feed-in Revenue
A3: Cost component | B3: Case 1 | C3: Case 2 | F3: Formula logic
A4: PV annualized CAPEX | B4: ='Economic Assumptions'!$D$7*('Economic Assumptions'!$D$4*(1+'Economic Assumptions'!$D$4)^'Economic Assumptions'!$D$8/((1+'Economic Assumptions'!$D$4)^'Economic Assumptions'!$D$8-1)) -> 4693.6031 | C4: ='Economic Assumptions'!$D$7*('Economic Assumptions'!$D$4*(1+'Economic Assumptions'!$D$4)^'Economic Assumptions'!$D$8/((1+'Economic Assumptions'!$D$4)^'Economic Assumptions'!$D$8-1)) -> 4693.6031 | F4: PV CAPEX × CRF(PV life)
A5: Electrolyzer annualized CAPEX | B5: ='Economic Assumptions'!$D$13*('Economic Assumptions'!$D$4*(1+'Economic Assumptions'!$D$4)^'Economic Assumptions'!$D$14/((1+'Economic Assumptions'!$D$4)^'Economic Assumptions'!$D$14-1)) -> 5231.0734 | C5: ='Economic Assumptions'!$D$13*('Economic Assumptions'!$D$4*(1+'Economic Assumptions'!$D$4)^'Economic Assumptions'!$D$14/((1+'Economic Assumptions'!$D$4)^'Economic Assumptions'!$D$14-1)) -> 5231.0734 | F5: ELY CAPEX × CRF(ELY life)
A6: Compressor annualized CAPEX | B6: =0*('Economic Assumptions'!$D$19*('Economic Assumptions'!$D$4*(1+'Economic Assumptions'!$D$4)^'Economic Assumptions'!$D$20/((1+'Economic Assumptions'!$D$4)^'Economic Assumptions'!$D$20-1))) -> 0 | C6: =1*('Economic Assumptions'!$D$19*('Economic Assumptions'!$D$4*(1+'Economic Assumptions'!$D$4)^'Economic Assumptions'!$D$20/((1+'Economic Assumptions'!$D$4)^'Economic Assumptions'!$D$20-1))) -> 1029.6276 | F6: Compressor CAPEX × CRF; zero in Case 1
A7: LP storage CAPEX | B7: ='Case Inputs'!C12*'Economic Assumptions'!$D$23 -> 6960 | C7: ='Case Inputs'!D12*'Economic Assumptions'!$D$23 -> 0 | F7: LP capacity × LP €/kg
A8: HP storage CAPEX | B8: ='Case Inputs'!C13*'Economic Assumptions'!$D$24 -> 0 | C8: ='Case Inputs'!D13*'Economic Assumptions'!$D$24 -> 5251.584 | F8: HP capacity × HP €/kg
A9: LP storage annualized CAPEX | B9: =B7*('Economic Assumptions'!$D$4*(1+'Economic Assumptions'!$D$4)^'Economic Assumptions'!$D$25/((1+'Economic Assumptions'!$D$4)^'Economic Assumptions'!$D$25-1)) -> 606.80452 | C9: =C7*('Economic Assumptions'!$D$4*(1+'Economic Assumptions'!$D$4)^'Economic Assumptions'!$D$25/((1+'Economic Assumptions'!$D$4)^'Economic Assumptions'!$D$25-1)) -> 0 | F9: LP CAPEX × CRF(storage life)
A10: HP storage annualized CAPEX | B10: =B8*('Economic Assumptions'!$D$4*(1+'Economic Assumptions'!$D$4)^'Economic Assumptions'!$D$25/((1+'Economic Assumptions'!$D$4)^'Economic Assumptions'!$D$25-1)) -> 0 | C10: =C8*('Economic Assumptions'!$D$4*(1+'Economic Assumptions'!$D$4)^'Economic Assumptions'!$D$25/((1+'Economic Assumptions'!$D$4)^'Economic Assumptions'!$D$25-1)) -> 457.85702 | F10: HP CAPEX × CRF(storage life)
A11: PV O&M | B11: ='Economic Assumptions'!$D$7*'Economic Assumptions'!$D$9 -> 3000 | C11: ='Economic Assumptions'!$D$7*'Economic Assumptions'!$D$9 -> 3000 | F11: PV CAPEX × PV O&M rate
A12: Electrolyzer O&M | B12: ='Economic Assumptions'!$D$13*'Economic Assumptions'!$D$15 -> 1200 | C12: ='Economic Assumptions'!$D$13*'Economic Assumptions'!$D$15 -> 1200 | F12: ELY CAPEX × ELY O&M rate
A13: Compressor O&M | B13: =0*'Economic Assumptions'!$D$19*'Economic Assumptions'!$D$21 -> 0 | C13: =1*'Economic Assumptions'!$D$19*'Economic Assumptions'!$D$21 -> 400 | F13: Compressor CAPEX × O&M; zero in Case 1
A14: Storage O&M | B14: =(B7+B8)*'Economic Assumptions'!$D$26 -> 69.6 | C14: =(C7+C8)*'Economic Assumptions'!$D$26 -> 52.51584 | F14: (LP + HP CAPEX) × storage O&M
A15: Stack replacement interval | B15: ='Economic Assumptions'!D17/'Case Inputs'!C28 -> 14.635586 | C15: ='Economic Assumptions'!D17/'Case Inputs'!D28 -> 14.635586 | F15: Stack durability / FLH of electrolyzer
A16: Stack replacement annual reserve | B16: =IF('Case Inputs'!C28>0,'Economic Assumptions'!$D$13*'Economic Assumptions'!$D$16*'Case Inputs'!C28/'Economic Assumptions'!$D$17,IF('Case Inputs'!C6=0,0,'Economic Assumptions'!$D$13*'Economic Assumptions'!$D$16*('Case Inputs'!C6*'Economic Assumptions'!$D$29/10)/'Economic Assumptions'!$D$17)) -> 1024.8992 | C16: =IF('Case Inputs'!D28>0,'Economic Assumptions'!$D$13*'Economic Assumptions'!$D$16*'Case Inputs'!D28/'Economic Assumptions'!$D$17,IF('Case Inputs'!D6=0,0,'Economic Assumptions'!$D$13*'Economic Assumptions'!$D$16*('Case Inputs'!D6*'Economic Assumptions'!$D$29/10)/'Economic Assumptions'!$D$17)) -> 1024.8992 | F16: Stack replacement reserve using FLH
A17: Annual grid electricity cost | B17: ='Case Inputs'!C10 -> 2821.31 | C17: ='Case Inputs'!D10 -> 1309.66 | F17: Linked total grid cost from optimization
A18: Feed-in revenue | B18: ='Case Inputs'!C27 -> 3077.94 | C18: ='Case Inputs'!D27 -> 3056.94 | F18: PV export × feed-in tariff
A19: Total annualized CAPEX | B19: =SUM(B4:B6,B9:B10) -> 10531.481 | C19: =SUM(C4:C6,C9:C10) -> 11412.161 | F19: Sum annualized CAPEX
A20: Gross annual OPEX | B20: =SUM(B11:B17) -> 8130.4448 | C20: =SUM(C11:C17) -> 7001.7106 | F20: O&M + replacement + grid cost
A21: Gross annual system cost | B21: =B19+B20 -> 18661.926 | C21: =C19+C20 -> 18413.872 | F21: CAPEX + gross OPEX
A22: Net annual system cost | B22: =B21-B18 -> 15583.986 | C22: =C21-C18 -> 15356.932 | F22: Gross cost − feed-in revenue

Sheet LCOH 
A1: Levelized Cost of Hydrogen by Case – Gross, Net
A3: Metric | B3: Case 1 | C3: Case 2
A4: Annual H₂ production (kg/yr) | B4: ='Case Inputs'!C6 -> 738.4 | C4: ='Case Inputs'!D6 -> 738.4
A5: H₂ supplied to roaster (kg/yr) | B5: ='Case Inputs'!C17 -> 738.4 | C5: ='Case Inputs'!D17 -> 738.4
A6: PV contribution (€/kg produced) | B6: ='Annualized Costs'!B4/B4 -> 6.3564506 | C6: ='Annualized Costs'!C4/C4 -> 6.3564506
A7: Electrolyzer contribution (€/kg produced) | B7: ='Annualized Costs'!B5/B4 -> 7.0843356 | C7: ='Annualized Costs'!C5/C4 -> 7.0843356
A8: Compressor contribution (€/kg produced) | B8: ='Annualized Costs'!B6/B4 -> 0 | C8: ='Annualized Costs'!C6/C4 -> 1.3944036
A9: LP storage contribution (€/kg produced) | B9: ='Annualized Costs'!B9/B4 -> 0.82178293 | C9: ='Annualized Costs'!C9/C4 -> 0
A10: HP storage contribution (€/kg produced) | B10: ='Annualized Costs'!B10/B4 -> 0 | C10: ='Annualized Costs'!C10/C4 -> 0.62006639
A11: O&M + replacement contribution (€/kg produced) | B11: =SUM('Annualized Costs'!B11:B16)/B4 -> 7.1900525 | C11: =SUM('Annualized Costs'!C11:C16)/C4 -> 7.7086276
A12: Grid electricity contribution (€/kg produced) | B12: ='Annualized Costs'!B17/B4 -> 3.8208424 | C12: ='Annualized Costs'!C17/C4 -> 1.7736457
A13: Feed-in revenue credit (€/kg produced) | B13: ='Annualized Costs'!B18/B4 -> 4.1683911 | C13: ='Annualized Costs'!C18/C4 -> 4.1399512
A14: Gross production LCOH (€/kg) | B14: ='Annualized Costs'!B21/B4 -> 25.273464 | C14: ='Annualized Costs'!C21/C4 -> 24.93753 | F14: *without revenue, all annual costs dividied by annual H2 produced
A15: Net production LCOH (€/kg) | B15: ='Annualized Costs'!B22/B4 -> 21.105073 | C15: ='Annualized Costs'!C22/C4 -> 20.797578 | F15: *with revenue, (annual cost - feed in revenue)/annual H2 produced
A16: Gross annual system cost (€/yr) | B16: ='Annualized Costs'!B21 -> 18661.926 | C16: ='Annualized Costs'!C21 -> 18413.872
A17: Net annual system cost (€/yr) | B17: ='Annualized Costs'!B22 -> 15583.986 | C17: ='Annualized Costs'!C22 -> 15356.932

Sheet OAT-Sensitivity
A1: LCOH Sensitivity Analysis | O1: Sensitivity Calculation
A2: METHOD | B2: One-at-a-time (OAT) | O2: Case index | P2: Annual H2 | Q2: Base total | R2: PV CAPEX | S2: PV life | T2: PV O&M | U2: ELY CAPEX | V2: ELY life | W2: ELY O&M | X2: Stack share | Y2: Stack durability | Z2: Comp CAPEX | AA2: Comp life | AB2: Comp O&M | AC2: LP CAPEX | AD2: HP CAPEX | AE2: Storage life | AF2: Storage O&M | AG2: Grid cost | AH2: Grid energy | AI2: Comp energy | AJ2: Rate | AK2: ELY SEC | AL2: Comp SEC
A3: Selected case | B3: Case 1 | O3: =MATCH($B$3,'Case Inputs'!$C$3:$D$3,0) -> 1 | P3: =INDEX('Case Inputs'!$C$6:$F$6,1,$O$3) -> 738.4 | Q3: =INDEX('Annualized Costs'!$B$22:$E$22,1,$O$3) -> 15583.986 | R3: ='Economic Assumptions'!$D$7 -> 60000 | S3: ='Economic Assumptions'!$D$8 -> 25 | T3: ='Economic Assumptions'!$D$9 -> 0.05 | U3: ='Economic Assumptions'!$D$13 -> 60000 | V3: ='Economic Assumptions'!$D$14 -> 20 | W3: ='Economic Assumptions'!$D$15 -> 0.02 | X3: ='Economic Assumptions'!$D$16 -> 0.25 | Y3: ='Economic Assumptions'!$D$17 -> 60000 | Z3: ='Economic Assumptions'!$D$19 -> 10000 | AA3: ='Economic Assumptions'!$D$20 -> 15 | AB3: ='Economic Assumptions'!$D$21 -> 0.04 | AC3: =INDEX('Annualized Costs'!$B$7:$E$7,1,$O$3) -> 6960 | AD3: =INDEX('Annualized Costs'!$B$8:$E$8,1,$O$3) -> 0 | AE3: ='Economic Assumptions'!$D$25 -> 20 | AF3: ='Economic Assumptions'!$D$26 -> 0.01 | AG3: =INDEX('Case Inputs'!$C$10:$F$10,1,$O$3) -> 2821.31 | AH3: =INDEX('Case Inputs'!$C$8:$F$8,1,$O$3) -> 30640 | AI3: =INDEX('Case Inputs'!$C$11:$F$11,1,$O$3) -> 0 | AJ3: ='Economic Assumptions'!$D$4 -> 0.06 | AK3: 55.52 | AL3: 1.01
A4: Base LCOH (€/kg) | B4: =INDEX('LCOH '!$B$15:$E$15,1,MATCH($B$3,'LCOH '!$B$3:$E$3,0)) -> 21.105073
A6: One-at-a-Time Sensitivity Inputs and Results | O6: Tornado Chart Data
A7: Parameter | B7: Unit | C7: Base | D7: Low | E7: High | F7: Low LCOH | G7: High LCOH | H7: Low Δ | I7: High Δ | J7: Lower endpoint | K7: Range | L7: Rank | M7: Method | O7: Parameter | P7: Low Δ | Q7: High Δ | R7: Impact
A8: Grid electricity cost | B8: multiplier | C8: 1 | D8: 0.8 | E8: 1.2 | F8: =($Q$3-$AG$3+$AG$3*$D8)/$P$3 -> 20.340904 | G8: =($Q$3-$AG$3+$AG$3*$E8)/$P$3 -> 21.869241 | H8: =F8-$B$4 -> -0.76416847 | I8: =G8-$B$4 -> 0.76416847 | J8: =MIN(F8,G8) -> 20.340904 | K8: =ABS(G8-F8) -> 1.5283369 | L8: =RANK(K8,$K$8:$K$19,0) -> 5 | M8: Scale annual grid cost | O8: =A14 -> Discount rate | P8: =H14 -> -2.3885824 | Q8: =I14 -> 2.5856847 | R8: =K14 -> 4.9742672
A9: PV Investment CAPEX | B9: multiplier | C9: 1 | D9: 0.8 | E9: 1.2 | F9: =($Q$3-INDEX('Annualized Costs'!$B$4:$E$4,1,$O$3)-INDEX('Annualized Costs'!$B$11:$E$11,1,$O$3)+(INDEX('Annualized Costs'!$B$4:$E$4,1,$O$3)+INDEX('Annualized Costs'!$B$11:$E$11,1,$O$3))*$D9)/$P$3 -> 19.021215 | G9: =($Q$3-INDEX('Annualized Costs'!$B$4:$E$4,1,$O$3)-INDEX('Annualized Costs'!$B$11:$E$11,1,$O$3)+(INDEX('Annualized Costs'!$B$4:$E$4,1,$O$3)+INDEX('Annualized Costs'!$B$11:$E$11,1,$O$3))*$E9)/$P$3 -> 23.188931 | H9: =F9-$B$4 -> -2.0838578 | I9: =G9-$B$4 -> 2.0838578 | J9: =MIN(F9,G9) -> 19.021215 | K9: =ABS(G9-F9) -> 4.1677157 | L9: =RANK(K9,$K$8:$K$19,0) -> 2 | M9: PV annualized CAPEX + PV O&M | O9: =A10 -> Electrolyzer CAPEX | P9: =H10 -> -2.0194942 | Q9: =I10 -> 2.0194942 | R9: =K10 -> 4.0389884
A10: Electrolyzer CAPEX | B10: multiplier | C10: 1 | D10: 0.8 | E10: 1.2 | F10: =($Q$3-SUM(INDEX('Annualized Costs'!$B$5:$E$5,1,$O$3),INDEX('Annualized Costs'!$B$12:$E$12,1,$O$3),INDEX('Annualized Costs'!$B$16:$E$16,1,$O$3))+SUM(INDEX('Annualized Costs'!$B$5:$E$5,1,$O$3),INDEX('Annualized Costs'!$B$12:$E$12,1,$O$3),INDEX('Annualized Costs'!$B$16:$E$16,1,$O$3))*$D10)/$P$3 -> 19.085579 | G10: =($Q$3-SUM(INDEX('Annualized Costs'!$B$5:$E$5,1,$O$3),INDEX('Annualized Costs'!$B$12:$E$12,1,$O$3),INDEX('Annualized Costs'!$B$16:$E$16,1,$O$3))+SUM(INDEX('Annualized Costs'!$B$5:$E$5,1,$O$3),INDEX('Annualized Costs'!$B$12:$E$12,1,$O$3),INDEX('Annualized Costs'!$B$16:$E$16,1,$O$3))*$E10)/$P$3 -> 23.124567 | H10: =F10-$B$4 -> -2.0194942 | I10: =G10-$B$4 -> 2.0194942 | J10: =MIN(F10,G10) -> 19.085579 | K10: =ABS(G10-F10) -> 4.0389884 | L10: =RANK(K10,$K$8:$K$19,0) -> 3 | M10: ELY annualized CAPEX + O&M + stack reserve | O10: =A9 -> PV Investment CAPEX | P10: =H9 -> -2.0838578 | Q10: =I9 -> 2.0838578 | R10: =K9 -> 4.1677157
A11: Compressor CAPEX | B11: multiplier | C11: 1 | D11: 0.8 | E11: 1.2 | F11: =($Q$3-SUM(INDEX('Annualized Costs'!$B$6:$E$6,1,$O$3),INDEX('Annualized Costs'!$B$13:$E$13,1,$O$3))+SUM(INDEX('Annualized Costs'!$B$6:$E$6,1,$O$3),INDEX('Annualized Costs'!$B$13:$E$13,1,$O$3))*$D11)/$P$3 -> 21.105073 | G11: =($Q$3-SUM(INDEX('Annualized Costs'!$B$6:$E$6,1,$O$3),INDEX('Annualized Costs'!$B$13:$E$13,1,$O$3))+SUM(INDEX('Annualized Costs'!$B$6:$E$6,1,$O$3),INDEX('Annualized Costs'!$B$13:$E$13,1,$O$3))*$E11)/$P$3 -> 21.105073 | H11: =F11-$B$4 -> 0 | I11: =G11-$B$4 -> 0 | J11: =MIN(F11,G11) -> 21.105073 | K11: =ABS(G11-F11) -> 0 | L11: =RANK(K11,$K$8:$K$19,0) -> 10 | M11: Compressor annualized CAPEX + O&M | O11: =A16 -> Electrolyzer lifetime | P11: =H16 -> 1.2820862 | Q11: =I16 -> -0.72788506 | R11: =K16 -> 2.0099712
A12: LP storage cost | B12: multiplier | C12: 1 | D12: 0.8 | E12: 1.2 | F12: =($Q$3-INDEX('Annualized Costs'!$B$9:$E$9,1,$O$3)-INDEX('Annualized Costs'!$B$7:$E$7,1,$O$3)*'Economic Assumptions'!$D$26+(INDEX('Annualized Costs'!$B$9:$E$9,1,$O$3)+INDEX('Annualized Costs'!$B$7:$E$7,1,$O$3)*'Economic Assumptions'!$D$26)*$D12)/$P$3 -> 20.921865 | G12: =($Q$3-INDEX('Annualized Costs'!$B$9:$E$9,1,$O$3)-INDEX('Annualized Costs'!$B$7:$E$7,1,$O$3)*'Economic Assumptions'!$D$26+(INDEX('Annualized Costs'!$B$9:$E$9,1,$O$3)+INDEX('Annualized Costs'!$B$7:$E$7,1,$O$3)*'Economic Assumptions'!$D$26)*$E12)/$P$3 -> 21.288281 | H12: =F12-$B$4 -> -0.18320816 | I12: =G12-$B$4 -> 0.18320816 | J12: =MIN(F12,G12) -> 20.921865 | K12: =ABS(G12-F12) -> 0.36641631 | L12: =RANK(K12,$K$8:$K$19,0) -> 8 | M12: LP annualized CAPEX + O&M | O12: =A8 -> Grid electricity cost | P12: =H8 -> -0.76416847 | Q12: =I8 -> 0.76416847 | R12: =K8 -> 1.5283369
A13: HP storage cost | B13: multiplier | C13: 1 | D13: 0.8 | E13: 1.2 | F13: =($Q$3-INDEX('Annualized Costs'!$B$10:$E$10,1,$O$3)-INDEX('Annualized Costs'!$B$8:$E$8,1,$O$3)*'Economic Assumptions'!$D$26+(INDEX('Annualized Costs'!$B$10:$E$10,1,$O$3)+INDEX('Annualized Costs'!$B$8:$E$8,1,$O$3)*'Economic Assumptions'!$D$26)*$D13)/$P$3 -> 21.105073 | G13: =($Q$3-INDEX('Annualized Costs'!$B$10:$E$10,1,$O$3)-INDEX('Annualized Costs'!$B$8:$E$8,1,$O$3)*'Economic Assumptions'!$D$26+(INDEX('Annualized Costs'!$B$10:$E$10,1,$O$3)+INDEX('Annualized Costs'!$B$8:$E$8,1,$O$3)*'Economic Assumptions'!$D$26)*$E13)/$P$3 -> 21.105073 | H13: =F13-$B$4 -> 0 | I13: =G13-$B$4 -> 0 | J13: =MIN(F13,G13) -> 21.105073 | K13: =ABS(G13-F13) -> 0 | L13: =RANK(K13,$K$8:$K$19,0) -> 10 | M13: HP annualized CAPEX + O&M | O13: =A15 -> PV lifetime | P13: =H15 -> 0.72788506 | Q13: =I15 -> -0.45323457 | R13: =K15 -> 1.1811196
A14: Discount rate | B14: % | C14: 0.06 | D14: 0.04 | E14: 0.08 | F14: =($Q$3-INDEX('Annualized Costs'!$B$4:$E$4,1,$O$3)-INDEX('Annualized Costs'!$B$5:$E$5,1,$O$3)-INDEX('Annualized Costs'!$B$6:$E$6,1,$O$3)-INDEX('Annualized Costs'!$B$9:$E$9,1,$O$3)-INDEX('Annualized Costs'!$B$10:$E$10,1,$O$3)+INDEX('Annualized Costs'!$B$4:$E$4,1,$O$3)*(($D14*(1+$D14)^'Economic Assumptions'!$D$8/((1+$D14)^'Economic Assumptions'!$D$8-1))/('Economic Assumptions'!$D$4*(1+'Economic Assumptions'!$D$4)^'Economic Assumptions'!$D$8/((1+'Economic Assumptions'!$D$4)^'Economic Assumptions'!$D$8-1)))+INDEX('Annualized Costs'!$B$5:$E$5,1,$O$3)*(($D14*(1+$D14)^'Economic Assumptions'!$D$14/((1+$D14)^'Economic Assumptions'!$D$14-1))/('Economic Assumptions'!$D$4*(1+'Economic Assumptions'!$D$4)^'Economic Assumptions'!$D$14/((1+'Economic Assumptions'!$D$4)^'Economic Assumptions'!$D$14-1)))+INDEX('Annualized Costs'!$B$6:$E$6,1,$O$3)*(($D14*(1+$D14)^'Economic Assumptions'!$D$20/((1+$D14)^'Economic Assumptions'!$D$20-1))/('Economic Assumptions'!$D$4*(1+'Economic Assumptions'!$D$4)^'Economic Assumptions'!$D$20/((1+'Economic Assumptions'!$D$4)^'Economic Assumptions'!$D$20-1)))+(INDEX('Annualized Costs'!$B$9:$E$9,1,$O$3)+INDEX('Annualized Costs'!$B$10:$E$10,1,$O$3))*(($D14*(1+$D14)^'Economic Assumptions'!$D$25/((1+$D14)^'Economic Assumptions'!$D$25-1))/('Economic Assumptions'!$D$4*(1+'Economic Assumptions'!$D$4)^'Economic Assumptions'!$D$25/((1+'Economic Assumptions'!$D$4)^'Economic Assumptions'!$D$25-1))))/$P$3 -> 18.71649 | G14: =($Q$3-INDEX('Annualized Costs'!$B$4:$E$4,1,$O$3)-INDEX('Annualized Costs'!$B$5:$E$5,1,$O$3)-INDEX('Annualized Costs'!$B$6:$E$6,1,$O$3)-INDEX('Annualized Costs'!$B$9:$E$9,1,$O$3)-INDEX('Annualized Costs'!$B$10:$E$10,1,$O$3)+INDEX('Annualized Costs'!$B$4:$E$4,1,$O$3)*(($E14*(1+$E14)^'Economic Assumptions'!$D$8/((1+$E14)^'Economic Assumptions'!$D$8-1))/('Economic Assumptions'!$D$4*(1+'Economic Assumptions'!$D$4)^'Economic Assumptions'!$D$8/((1+'Economic Assumptions'!$D$4)^'Economic Assumptions'!$D$8-1)))+INDEX('Annualized Costs'!$B$5:$E$5,1,$O$3)*(($E14*(1+$E14)^'Economic Assumptions'!$D$14/((1+$E14)^'Economic Assumptions'!$D$14-1))/('Economic Assumptions'!$D$4*(1+'Economic Assumptions'!$D$4)^'Economic Assumptions'!$D$14/((1+'Economic Assumptions'!$D$4)^'Economic Assumptions'!$D$14-1)))+INDEX('Annualized Costs'!$B$6:$E$6,1,$O$3)*(($E14*(1+$E14)^'Economic Assumptions'!$D$20/((1+$E14)^'Economic Assumptions'!$D$20-1))/('Economic Assumptions'!$D$4*(1+'Economic Assumptions'!$D$4)^'Economic Assumptions'!$D$20/((1+'Economic Assumptions'!$D$4)^'Economic Assumptions'!$D$20-1)))+(INDEX('Annualized Costs'!$B$9:$E$9,1,$O$3)+INDEX('Annualized Costs'!$B$10:$E$10,1,$O$3))*(($E14*(1+$E14)^'Economic Assumptions'!$D$25/((1+$E14)^'Economic Assumptions'!$D$25-1))/('Economic Assumptions'!$D$4*(1+'Economic Assumptions'!$D$4)^'Economic Assumptions'!$D$25/((1+'Economic Assumptions'!$D$4)^'Economic Assumptions'!$D$25-1))))/$P$3 -> 23.690758 | H14: =F14-$B$4 -> -2.3885824 | I14: =G14-$B$4 -> 2.5856847 | J14: =MIN(F14,G14) -> 18.71649 | K14: =ABS(G14-F14) -> 4.9742672 | L14: =RANK(K14,$K$8:$K$19,0) -> 1 | M14: Recalculate all CRFs | O14: =A18 -> Electrolyzer SEC | P14: =H18 -> -0.19131739 | Q14: =I18 -> 0.19131739 | R14: =K18 -> 0.38263479
A15: PV lifetime | B15: years | C15: 25 | D15: 20 | E15: 30 | F15: =($Q$3-INDEX('Annualized Costs'!$B$4:$E$4,1,$O$3)+INDEX('Annualized Costs'!$B$4:$E$4,1,$O$3)*(('Economic Assumptions'!$D$4*(1+'Economic Assumptions'!$D$4)^$D15/((1+'Economic Assumptions'!$D$4)^$D15-1))/('Economic Assumptions'!$D$4*(1+'Economic Assumptions'!$D$4)^'Economic Assumptions'!$D$8/((1+'Economic Assumptions'!$D$4)^'Economic Assumptions'!$D$8-1))))/$P$3 -> 21.832958 | G15: =($Q$3-INDEX('Annualized Costs'!$B$4:$E$4,1,$O$3)+INDEX('Annualized Costs'!$B$4:$E$4,1,$O$3)*(('Economic Assumptions'!$D$4*(1+'Economic Assumptions'!$D$4)^$E15/((1+'Economic Assumptions'!$D$4)^$E15-1))/('Economic Assumptions'!$D$4*(1+'Economic Assumptions'!$D$4)^'Economic Assumptions'!$D$8/((1+'Economic Assumptions'!$D$4)^'Economic Assumptions'!$D$8-1))))/$P$3 -> 20.651838 | H15: =F15-$B$4 -> 0.72788506 | I15: =G15-$B$4 -> -0.45323457 | J15: =MIN(F15,G15) -> 20.651838 | K15: =ABS(G15-F15) -> 1.1811196 | L15: =RANK(K15,$K$8:$K$19,0) -> 6 | M15: Recalculate PV CRF | O15: =A12 -> LP storage cost | P15: =H12 -> -0.18320816 | Q15: =I12 -> 0.18320816 | R15: =K12 -> 0.36641631
A16: Electrolyzer lifetime | B16: years | C16: 20 | D16: 15 | E16: 25 | F16: =($Q$3-INDEX('Annualized Costs'!$B$5:$E$5,1,$O$3)+INDEX('Annualized Costs'!$B$5:$E$5,1,$O$3)*(('Economic Assumptions'!$D$4*(1+'Economic Assumptions'!$D$4)^$D16/((1+'Economic Assumptions'!$D$4)^$D16-1))/('Economic Assumptions'!$D$4*(1+'Economic Assumptions'!$D$4)^'Economic Assumptions'!$D$14/((1+'Economic Assumptions'!$D$4)^'Economic Assumptions'!$D$14-1))))/$P$3 -> 22.387159 | G16: =($Q$3-INDEX('Annualized Costs'!$B$5:$E$5,1,$O$3)+INDEX('Annualized Costs'!$B$5:$E$5,1,$O$3)*(('Economic Assumptions'!$D$4*(1+'Economic Assumptions'!$D$4)^$E16/((1+'Economic Assumptions'!$D$4)^$E16-1))/('Economic Assumptions'!$D$4*(1+'Economic Assumptions'!$D$4)^'Economic Assumptions'!$D$14/((1+'Economic Assumptions'!$D$4)^'Economic Assumptions'!$D$14-1))))/$P$3 -> 20.377188 | H16: =F16-$B$4 -> 1.2820862 | I16: =G16-$B$4 -> -0.72788506 | J16: =MIN(F16,G16) -> 20.377188 | K16: =ABS(G16-F16) -> 2.0099712 | L16: =RANK(K16,$K$8:$K$19,0) -> 4 | M16: Recalculate ELY CRF | O16: =A17 -> Storage lifetime | P16: =H17 -> 0.14872199 | Q16: =I17 -> -0.084434667 | R16: =K17 -> 0.23315666
A17: Storage lifetime | B17: years | C17: 20 | D17: 15 | E17: 25 | F17: =($Q$3-INDEX('Annualized Costs'!$B$9:$E$9,1,$O$3)-INDEX('Annualized Costs'!$B$10:$E$10,1,$O$3)+(INDEX('Annualized Costs'!$B$9:$E$9,1,$O$3)+INDEX('Annualized Costs'!$B$10:$E$10,1,$O$3))*(('Economic Assumptions'!$D$4*(1+'Economic Assumptions'!$D$4)^$D17/((1+'Economic Assumptions'!$D$4)^$D17-1))/('Economic Assumptions'!$D$4*(1+'Economic Assumptions'!$D$4)^'Economic Assumptions'!$D$25/((1+'Economic Assumptions'!$D$4)^'Economic Assumptions'!$D$25-1))))/$P$3 -> 21.253795 | G17: =($Q$3-INDEX('Annualized Costs'!$B$9:$E$9,1,$O$3)-INDEX('Annualized Costs'!$B$10:$E$10,1,$O$3)+(INDEX('Annualized Costs'!$B$9:$E$9,1,$O$3)+INDEX('Annualized Costs'!$B$10:$E$10,1,$O$3))*(('Economic Assumptions'!$D$4*(1+'Economic Assumptions'!$D$4)^$E17/((1+'Economic Assumptions'!$D$4)^$E17-1))/('Economic Assumptions'!$D$4*(1+'Economic Assumptions'!$D$4)^'Economic Assumptions'!$D$25/((1+'Economic Assumptions'!$D$4)^'Economic Assumptions'!$D$25-1))))/$P$3 -> 21.020638 | H17: =F17-$B$4 -> 0.14872199 | I17: =G17-$B$4 -> -0.084434667 | J17: =MIN(F17,G17) -> 21.020638 | K17: =ABS(G17-F17) -> 0.23315666 | L17: =RANK(K17,$K$8:$K$19,0) -> 9 | M17: Recalculate storage CRFs | O17: =A11 -> Compressor CAPEX | P17: =H11 -> 0 | Q17: =I11 -> 0 | R17: =K11 -> 0
A18: Electrolyzer SEC | B18: kWh/kg | C18: 55.52 | D18: 52.74 | E18: 58.3 | F18: =($Q$3-$AG$3+$AG$3*($D18/$C18))/$P$3 -> 20.913755 | G18: =($Q$3-$AG$3+$AG$3*($E18/$C18))/$P$3 -> 21.29639 | H18: =F18-$B$4 -> -0.19131739 | I18: =G18-$B$4 -> 0.19131739 | J18: =MIN(F18,G18) -> 20.913755 | K18: =ABS(G18-F18) -> 0.38263479 | L18: =RANK(K18,$K$8:$K$19,0) -> 7 | M18: Scale grid cost at fixed dispatch shares | O18: =A13 -> HP storage cost | P18: =H13 -> 0 | Q18: =I13 -> 0 | R18: =K13 -> 0
A19: Compressor SEC | B19: kWh/kg | C19: 1.01 | D19: 0.8 | E19: 1.3 | F19: =($Q$3-($AI$3*IF($AH$3=0,0,$AG$3/$AH$3))+($AI$3*($D19/$C19)*IF($AH$3=0,0,$AG$3/$AH$3)))/$P$3 -> 21.105073 | G19: =($Q$3-($AI$3*IF($AH$3=0,0,$AG$3/$AH$3))+($AI$3*($E19/$C19)*IF($AH$3=0,0,$AG$3/$AH$3)))/$P$3 -> 21.105073 | H19: =F19-$B$4 -> 0 | I19: =G19-$B$4 -> 0 | J19: =MIN(F19,G19) -> 21.105073 | K19: =ABS(G19-F19) -> 0 | L19: =RANK(K19,$K$8:$K$19,0) -> 10 | M19: Scale compressor-related grid energy | O19: =A19 -> Compressor SEC | P19: =H19 -> 0 | Q19: =I19 -> 0 | R19: =K19 -> 0
B47: Findings
A48: Case 1 and 2 | B48: 1. Discount rate has highest influence, suggests that project economics depends on financing conditions and cost of capital.
B49: 2. PV CAPEX is the major driver
B50: 3. Electrolyzer CAPEX is equally important

Sheet OAT Scenario Curves
A1: Scenario Curves
A3: Selected case | B3: Case 1 | Y3: Case idx | Z3: =MATCH($B$3, 'LCOH '!$B$3:'LCOH '!$E$3,0) -> 1
A4: Base LCOH | B4: =INDEX('LCOH '!$B$15:$E$15,1,MATCH($B$3,'LCOH '!$B$3:$E$3,0)) -> 21.105073 | Y4: Annual H2 | Z4: {=INDEX('Case Inputs'!$C$6:$F$6,1,'OAT Scenario Curves'!$Z$3)} -> 738.4
Y5: Base net annual system cost | Z5: {=INDEX('Annualized Costs'!$B$22:'Annualized Costs'!$E$22,1,'OAT Scenario Curves'!$Z$3)} -> 15583.986
A6: Electrolyzer CAPEX | F6: PV CAPEX | K6: Electrolyzer SEC Curve | P6: Discount Rate | U6: Grid Cost Curve | Y6: Base total grid cost | Z6: {=INDEX('Annualized Costs'!$B$17:$E$17,1,'OAT Scenario Curves'!$Z$3)} -> 2821.31
A7: Multiplier | B7: LCOH | C7: Change | D7: Selected Case | F7: Multiplier | G7: LCOH | H7: Change | I7: Selected Case | K7: ELY SEC (kWh/kg) | L7: LCOH | M7: Change | N7: Selected case | P7: Rate | Q7: LCOH | R7: Change | S7: Selected case | U7: Multiplier | V7: LCOH | W7: Change | X7: Selected case | Y7: Base net LCOH | Z7: =$Z$5/$Z$4 -> 21.105073
A8: 0.5 | B8: {=($Z$5-INDEX('Annualized Costs'!$B$5:$E$5,1,$Z$3)+INDEX('Annualized Costs'!$B$5:$E$5,1,$Z$3)*A8)/$Z$4} -> 17.562905 | C8: =B8-$B$4 -> -3.5421678 | D8: =$B$3 -> Case 1 | F8: 0.5 | G8: {=($Z$5-INDEX('Annualized Costs'!$B$4:$E$4,1,$Z$3)+INDEX('Annualized Costs'!$B$4:$E$4,1,$Z$3)*F8)/$Z$4} -> 17.926848 | H8: =G8-$B$4 -> -3.1782253 | I8: =$B$3 -> Case 1 | K8: 50 | L8: =($Z$5-$Z$8+$Z$8*(K8/'Economic Assumptions'!$D$29))/'OAT Scenario Curves'!$Z$4 -> 20.767683 | M8: =L8-$B$4 -> -0.33739 | N8: =$B$3 -> Case 1 | P8: =P13*0.5 -> 0.03 | Q8: =($Z$5-INDEX('Annualized Costs'!$B$4:$E$4,1,$Z$3)-INDEX('Annualized Costs'!$B$5:$E$5,1,$Z$3)-INDEX('Annualized Costs'!$B$6:$E$6,1,$Z$3)-INDEX('Annualized Costs'!$B$9:$E$9,1,$Z$3)-INDEX('Annualized Costs'!$B$10:$E$10,1,$Z$3)+INDEX('Annualized Costs'!$B$4:$E$4,1,$Z$3)*((P8*(1+P8)^'Economic Assumptions'!$D$8/((1+P8)^'Economic Assumptions'!$D$8-1))/('Economic Assumptions'!$D$4*(1+'Economic Assumptions'!$D$4)^'Economic Assumptions'!$D$8/((1+'Economic Assumptions'!$D$4)^'Economic Assumptions'!$D$8-1)))+INDEX('Annualized Costs'!$B$5:$E$5,1,$Z$3)*((P8*(1+P8)^'Economic Assumptions'!$D$14/((1+P8)^'Economic Assumptions'!$D$14-1))/('Economic Assumptions'!$D$4*(1+'Economic Assumptions'!$D$4)^'Economic Assumptions'!$D$14/((1+'Economic Assumptions'!$D$4)^'Economic Assumptions'!$D$14-1)))+INDEX('Annualized Costs'!$B$6:$E$6,1,$Z$3)*((P8*(1+P8)^'Economic Assumptions'!$D$20/((1+P8)^'Economic Assumptions'!$D$20-1))/('Economic Assumptions'!$D$4*(1+'Economic Assumptions'!$D$4)^'Economic Assumptions'!$D$20/((1+'Economic Assumptions'!$D$4)^'Economic Assumptions'!$D$20-1)))+(INDEX('Annualized Costs'!$B$9:$E$9,1,$Z$3)+INDEX('Annualized Costs'!$B$10:$E$10,1,$Z$3))*((P8*(1+P8)^'Economic Assumptions'!$D$25/((1+P8)^'Economic Assumptions'!$D$25-1))/('Economic Assumptions'!$D$4*(1+'Economic Assumptions'!$D$4)^'Economic Assumptions'!$D$25/((1+'Economic Assumptions'!$D$4)^'Economic Assumptions'!$D$25-1))))/$Z$4 -> 17.604199 | R8: =Q8-$B$4 -> -3.5008735 | S8: =$B$3 -> Case 1 | U8: 0.5 | V8: =($Z$5-$Z$6+$Z$6*U8)/$Z$4 -> 19.194652 | W8: =V8-$B$4 -> -1.9104212 | X8: =$B$3 -> Case 1 | Y8: Grid Cost - Electrolyzer | Z8: {=INDEX('Case Inputs'!$C$22:$F$22,1,'OAT Scenario Curves'!$Z$3)} -> 2505.73
A9: =A8+0.1 -> 0.6 | B9: {=($Z$5-INDEX('Annualized Costs'!$B$5:$E$5,1,$Z$3)+INDEX('Annualized Costs'!$B$5:$E$5,1,$Z$3)*A9)/$Z$4} -> 18.271339 | C9: =B9-$B$4 -> -2.8337342 | D9: =$B$3 -> Case 1 | F9: =F8+0.1 -> 0.6 | G9: {=($Z$5-INDEX('Annualized Costs'!$B$4:$E$4,1,$Z$3)+INDEX('Annualized Costs'!$B$4:$E$4,1,$Z$3)*F9)/$Z$4} -> 18.562493 | H9: =G9-$B$4 -> -2.5425802 | I9: =$B$3 -> Case 1 | K9: 52 | L9: =($Z$5-$Z$8+$Z$8*(K9/'Economic Assumptions'!$D$29))/'OAT Scenario Curves'!$Z$4 -> 20.889926 | M9: =L9-$B$4 -> -0.21514725 | N9: =$B$3 -> Case 1 | P9: =P13*0.6 -> 0.036 | Q9: =($Z$5-INDEX('Annualized Costs'!$B$4:$E$4,1,$Z$3)-INDEX('Annualized Costs'!$B$5:$E$5,1,$Z$3)-INDEX('Annualized Costs'!$B$6:$E$6,1,$Z$3)-INDEX('Annualized Costs'!$B$9:$E$9,1,$Z$3)-INDEX('Annualized Costs'!$B$10:$E$10,1,$Z$3)+INDEX('Annualized Costs'!$B$4:$E$4,1,$Z$3)*((P9*(1+P9)^'Economic Assumptions'!$D$8/((1+P9)^'Economic Assumptions'!$D$8-1))/('Economic Assumptions'!$D$4*(1+'Economic Assumptions'!$D$4)^'Economic Assumptions'!$D$8/((1+'Economic Assumptions'!$D$4)^'Economic Assumptions'!$D$8-1)))+INDEX('Annualized Costs'!$B$5:$E$5,1,$Z$3)*((P9*(1+P9)^'Economic Assumptions'!$D$14/((1+P9)^'Economic Assumptions'!$D$14-1))/('Economic Assumptions'!$D$4*(1+'Economic Assumptions'!$D$4)^'Economic Assumptions'!$D$14/((1+'Economic Assumptions'!$D$4)^'Economic Assumptions'!$D$14-1)))+INDEX('Annualized Costs'!$B$6:$E$6,1,$Z$3)*((P9*(1+P9)^'Economic Assumptions'!$D$20/((1+P9)^'Economic Assumptions'!$D$20-1))/('Economic Assumptions'!$D$4*(1+'Economic Assumptions'!$D$4)^'Economic Assumptions'!$D$20/((1+'Economic Assumptions'!$D$4)^'Economic Assumptions'!$D$20-1)))+(INDEX('Annualized Costs'!$B$9:$E$9,1,$Z$3)+INDEX('Annualized Costs'!$B$10:$E$10,1,$Z$3))*((P9*(1+P9)^'Economic Assumptions'!$D$25/((1+P9)^'Economic Assumptions'!$D$25-1))/('Economic Assumptions'!$D$4*(1+'Economic Assumptions'!$D$4)^'Economic Assumptions'!$D$25/((1+'Economic Assumptions'!$D$4)^'Economic Assumptions'!$D$25-1))))/$Z$4 -> 18.264728 | R9: =Q9-$B$4 -> -2.8403446 | S9: =$B$3 -> Case 1 | U9: =U8+0.1 -> 0.6 | V9: =($Z$5-$Z$6+$Z$6*U9)/$Z$4 -> 19.576736 | W9: =V9-$B$4 -> -1.5283369 | X9: =$B$3 -> Case 1
A10: =A9+0.1 -> 0.7 | B10: {=($Z$5-INDEX('Annualized Costs'!$B$5:$E$5,1,$Z$3)+INDEX('Annualized Costs'!$B$5:$E$5,1,$Z$3)*A10)/$Z$4} -> 18.979772 | C10: =B10-$B$4 -> -2.1253007 | D10: =$B$3 -> Case 1 | F10: =F9+0.1 -> 0.7 | G10: {=($Z$5-INDEX('Annualized Costs'!$B$4:$E$4,1,$Z$3)+INDEX('Annualized Costs'!$B$4:$E$4,1,$Z$3)*F10)/$Z$4} -> 19.198138 | H10: =G10-$B$4 -> -1.9069352 | I10: =$B$3 -> Case 1 | K10: 54 | L10: =($Z$5-$Z$8+$Z$8*(K10/'Economic Assumptions'!$D$29))/'OAT Scenario Curves'!$Z$4 -> 21.012168 | M10: =L10-$B$4 -> -0.092904492 | N10: =$B$3 -> Case 1 | P10: =P13*0.7 -> 0.042 | Q10: =($Z$5-INDEX('Annualized Costs'!$B$4:$E$4,1,$Z$3)-INDEX('Annualized Costs'!$B$5:$E$5,1,$Z$3)-INDEX('Annualized Costs'!$B$6:$E$6,1,$Z$3)-INDEX('Annualized Costs'!$B$9:$E$9,1,$Z$3)-INDEX('Annualized Costs'!$B$10:$E$10,1,$Z$3)+INDEX('Annualized Costs'!$B$4:$E$4,1,$Z$3)*((P10*(1+P10)^'Economic Assumptions'!$D$8/((1+P10)^'Economic Assumptions'!$D$8-1))/('Economic Assumptions'!$D$4*(1+'Economic Assumptions'!$D$4)^'Economic Assumptions'!$D$8/((1+'Economic Assumptions'!$D$4)^'Economic Assumptions'!$D$8-1)))+INDEX('Annualized Costs'!$B$5:$E$5,1,$Z$3)*((P10*(1+P10)^'Economic Assumptions'!$D$14/((1+P10)^'Economic Assumptions'!$D$14-1))/('Economic Assumptions'!$D$4*(1+'Economic Assumptions'!$D$4)^'Economic Assumptions'!$D$14/((1+'Economic Assumptions'!$D$4)^'Economic Assumptions'!$D$14-1)))+INDEX('Annualized Costs'!$B$6:$E$6,1,$Z$3)*((P10*(1+P10)^'Economic Assumptions'!$D$20/((1+P10)^'Economic Assumptions'!$D$20-1))/('Economic Assumptions'!$D$4*(1+'Economic Assumptions'!$D$4)^'Economic Assumptions'!$D$20/((1+'Economic Assumptions'!$D$4)^'Economic Assumptions'!$D$20-1)))+(INDEX('Annualized Costs'!$B$9:$E$9,1,$Z$3)+INDEX('Annualized Costs'!$B$10:$E$10,1,$Z$3))*((P10*(1+P10)^'Economic Assumptions'!$D$25/((1+P10)^'Economic Assumptions'!$D$25-1))/('Economic Assumptions'!$D$4*(1+'Economic Assumptions'!$D$4)^'Economic Assumptions'!$D$25/((1+'Economic Assumptions'!$D$4)^'Economic Assumptions'!$D$25-1))))/$Z$4 -> 18.945726 | R10: =Q10-$B$4 -> -2.1593466 | S10: =$B$3 -> Case 1 | U10: =U9+0.1 -> 0.7 | V10: =($Z$5-$Z$6+$Z$6*U10)/$Z$4 -> 19.95882 | W10: =V10-$B$4 -> -1.1462527 | X10: =$B$3 -> Case 1
A11: =A10+0.1 -> 0.8 | B11: {=($Z$5-INDEX('Annualized Costs'!$B$5:$E$5,1,$Z$3)+INDEX('Annualized Costs'!$B$5:$E$5,1,$Z$3)*A11)/$Z$4} -> 19.688206 | C11: =B11-$B$4 -> -1.4168671 | D11: =$B$3 -> Case 1 | F11: =F10+0.1 -> 0.8 | G11: {=($Z$5-INDEX('Annualized Costs'!$B$4:$E$4,1,$Z$3)+INDEX('Annualized Costs'!$B$4:$E$4,1,$Z$3)*F11)/$Z$4} -> 19.833783 | H11: =G11-$B$4 -> -1.2712901 | I11: =$B$3 -> Case 1 | K11: 55.52 | L11: =($Z$5-$Z$8+$Z$8*(K11/'Economic Assumptions'!$D$29))/'OAT Scenario Curves'!$Z$4 -> 21.105073 | M11: =L11-$B$4 -> 0 | N11: =$B$3 -> Case 1 | P11: =P13*0.8 -> 0.048 | Q11: =($Z$5-INDEX('Annualized Costs'!$B$4:$E$4,1,$Z$3)-INDEX('Annualized Costs'!$B$5:$E$5,1,$Z$3)-INDEX('Annualized Costs'!$B$6:$E$6,1,$Z$3)-INDEX('Annualized Costs'!$B$9:$E$9,1,$Z$3)-INDEX('Annualized Costs'!$B$10:$E$10,1,$Z$3)+INDEX('Annualized Costs'!$B$4:$E$4,1,$Z$3)*((P11*(1+P11)^'Economic Assumptions'!$D$8/((1+P11)^'Economic Assumptions'!$D$8-1))/('Economic Assumptions'!$D$4*(1+'Economic Assumptions'!$D$4)^'Economic Assumptions'!$D$8/((1+'Economic Assumptions'!$D$4)^'Economic Assumptions'!$D$8-1)))+INDEX('Annualized Costs'!$B$5:$E$5,1,$Z$3)*((P11*(1+P11)^'Economic Assumptions'!$D$14/((1+P11)^'Economic Assumptions'!$D$14-1))/('Economic Assumptions'!$D$4*(1+'Economic Assumptions'!$D$4)^'Economic Assumptions'!$D$14/((1+'Economic Assumptions'!$D$4)^'Economic Assumptions'!$D$14-1)))+INDEX('Annualized Costs'!$B$6:$E$6,1,$Z$3)*((P11*(1+P11)^'Economic Assumptions'!$D$20/((1+P11)^'Economic Assumptions'!$D$20-1))/('Economic Assumptions'!$D$4*(1+'Economic Assumptions'!$D$4)^'Economic Assumptions'!$D$20/((1+'Economic Assumptions'!$D$4)^'Economic Assumptions'!$D$20-1)))+(INDEX('Annualized Costs'!$B$9:$E$9,1,$Z$3)+INDEX('Annualized Costs'!$B$10:$E$10,1,$Z$3))*((P11*(1+P11)^'Economic Assumptions'!$D$25/((1+P11)^'Economic Assumptions'!$D$25-1))/('Economic Assumptions'!$D$4*(1+'Economic Assumptions'!$D$4)^'Economic Assumptions'!$D$25/((1+'Economic Assumptions'!$D$4)^'Economic Assumptions'!$D$25-1))))/$Z$4 -> 19.646566 | R11: =Q11-$B$4 -> -1.4585068 | S11: =$B$3 -> Case 1 | U11: =U10+0.1 -> 0.8 | V11: =($Z$5-$Z$6+$Z$6*U11)/$Z$4 -> 20.340904 | W11: =V11-$B$4 -> -0.76416847 | X11: =$B$3 -> Case 1
A12: =A11+0.1 -> 0.9 | B12: {=($Z$5-INDEX('Annualized Costs'!$B$5:$E$5,1,$Z$3)+INDEX('Annualized Costs'!$B$5:$E$5,1,$Z$3)*A12)/$Z$4} -> 20.396639 | C12: =B12-$B$4 -> -0.70843356 | D12: =$B$3 -> Case 1 | F12: =F11+0.1 -> 0.9 | G12: {=($Z$5-INDEX('Annualized Costs'!$B$4:$E$4,1,$Z$3)+INDEX('Annualized Costs'!$B$4:$E$4,1,$Z$3)*F12)/$Z$4} -> 20.469428 | H12: =G12-$B$4 -> -0.63564506 | I12: =$B$3 -> Case 1 | K12: 57 | L12: =($Z$5-$Z$8+$Z$8*(K12/'Economic Assumptions'!$D$29))/'OAT Scenario Curves'!$Z$4 -> 21.195533 | M12: =L12-$B$4 -> 0.090459637 | N12: =$B$3 -> Case 1 | P12: =P13*0.9 -> 0.054 | Q12: =($Z$5-INDEX('Annualized Costs'!$B$4:$E$4,1,$Z$3)-INDEX('Annualized Costs'!$B$5:$E$5,1,$Z$3)-INDEX('Annualized Costs'!$B$6:$E$6,1,$Z$3)-INDEX('Annualized Costs'!$B$9:$E$9,1,$Z$3)-INDEX('Annualized Costs'!$B$10:$E$10,1,$Z$3)+INDEX('Annualized Costs'!$B$4:$E$4,1,$Z$3)*((P12*(1+P12)^'Economic Assumptions'!$D$8/((1+P12)^'Economic Assumptions'!$D$8-1))/('Economic Assumptions'!$D$4*(1+'Economic Assumptions'!$D$4)^'Economic Assumptions'!$D$8/((1+'Economic Assumptions'!$D$4)^'Economic Assumptions'!$D$8-1)))+INDEX('Annualized Costs'!$B$5:$E$5,1,$Z$3)*((P12*(1+P12)^'Economic Assumptions'!$D$14/((1+P12)^'Economic Assumptions'!$D$14-1))/('Economic Assumptions'!$D$4*(1+'Economic Assumptions'!$D$4)^'Economic Assumptions'!$D$14/((1+'Economic Assumptions'!$D$4)^'Economic Assumptions'!$D$14-1)))+INDEX('Annualized Costs'!$B$6:$E$6,1,$Z$3)*((P12*(1+P12)^'Economic Assumptions'!$D$20/((1+P12)^'Economic Assumptions'!$D$20-1))/('Economic Assumptions'!$D$4*(1+'Economic Assumptions'!$D$4)^'Economic Assumptions'!$D$20/((1+'Economic Assumptions'!$D$4)^'Economic Assumptions'!$D$20-1)))+(INDEX('Annualized Costs'!$B$9:$E$9,1,$Z$3)+INDEX('Annualized Costs'!$B$10:$E$10,1,$Z$3))*((P12*(1+P12)^'Economic Assumptions'!$D$25/((1+P12)^'Economic Assumptions'!$D$25-1))/('Economic Assumptions'!$D$4*(1+'Economic Assumptions'!$D$4)^'Economic Assumptions'!$D$25/((1+'Economic Assumptions'!$D$4)^'Economic Assumptions'!$D$25-1))))/$Z$4 -> 20.366581 | R12: =Q12-$B$4 -> -0.73849188 | S12: =$B$3 -> Case 1 | U12: =U11+0.1 -> 0.9 | V12: =($Z$5-$Z$6+$Z$6*U12)/$Z$4 -> 20.722989 | W12: =V12-$B$4 -> -0.38208424 | X12: =$B$3 -> Case 1
A13: =A12+0.1 -> 1 | B13: {=($Z$5-INDEX('Annualized Costs'!$B$5:$E$5,1,$Z$3)+INDEX('Annualized Costs'!$B$5:$E$5,1,$Z$3)*A13)/$Z$4} -> 21.105073 | C13: =B13-$B$4 -> 0 | D13: =$B$3 -> Case 1 | F13: =F12+0.1 -> 1 | G13: {=($Z$5-INDEX('Annualized Costs'!$B$4:$E$4,1,$Z$3)+INDEX('Annualized Costs'!$B$4:$E$4,1,$Z$3)*F13)/$Z$4} -> 21.105073 | H13: =G13-$B$4 -> 0 | I13: =$B$3 -> Case 1 | K13: 59 | L13: =($Z$5-$Z$8+$Z$8*(K13/'Economic Assumptions'!$D$29))/'OAT Scenario Curves'!$Z$4 -> 21.317775 | M13: =L13-$B$4 -> 0.21270239 | N13: =$B$3 -> Case 1 | P13: 0.06 | Q13: =($Z$5-INDEX('Annualized Costs'!$B$4:$E$4,1,$Z$3)-INDEX('Annualized Costs'!$B$5:$E$5,1,$Z$3)-INDEX('Annualized Costs'!$B$6:$E$6,1,$Z$3)-INDEX('Annualized Costs'!$B$9:$E$9,1,$Z$3)-INDEX('Annualized Costs'!$B$10:$E$10,1,$Z$3)+INDEX('Annualized Costs'!$B$4:$E$4,1,$Z$3)*((P13*(1+P13)^'Economic Assumptions'!$D$8/((1+P13)^'Economic Assumptions'!$D$8-1))/('Economic Assumptions'!$D$4*(1+'Economic Assumptions'!$D$4)^'Economic Assumptions'!$D$8/((1+'Economic Assumptions'!$D$4)^'Economic Assumptions'!$D$8-1)))+INDEX('Annualized Costs'!$B$5:$E$5,1,$Z$3)*((P13*(1+P13)^'Economic Assumptions'!$D$14/((1+P13)^'Economic Assumptions'!$D$14-1))/('Economic Assumptions'!$D$4*(1+'Economic Assumptions'!$D$4)^'Economic Assumptions'!$D$14/((1+'Economic Assumptions'!$D$4)^'Economic Assumptions'!$D$14-1)))+INDEX('Annualized Costs'!$B$6:$E$6,1,$Z$3)*((P13*(1+P13)^'Economic Assumptions'!$D$20/((1+P13)^'Economic Assumptions'!$D$20-1))/('Economic Assumptions'!$D$4*(1+'Economic Assumptions'!$D$4)^'Economic Assumptions'!$D$20/((1+'Economic Assumptions'!$D$4)^'Economic Assumptions'!$D$20-1)))+(INDEX('Annualized Costs'!$B$9:$E$9,1,$Z$3)+INDEX('Annualized Costs'!$B$10:$E$10,1,$Z$3))*((P13*(1+P13)^'Economic Assumptions'!$D$25/((1+P13)^'Economic Assumptions'!$D$25-1))/('Economic Assumptions'!$D$4*(1+'Economic Assumptions'!$D$4)^'Economic Assumptions'!$D$25/((1+'Economic Assumptions'!$D$4)^'Economic Assumptions'!$D$25-1))))/$Z$4 -> 21.105073 | R13: =Q13-$B$4 -> 0 | S13: =$B$3 -> Case 1 | U13: =U12+0.1 -> 1 | V13: =($Z$5-$Z$6+$Z$6*U13)/$Z$4 -> 21.105073 | W13: =V13-$B$4 -> 0 | X13: =$B$3 -> Case 1
A14: =A13+0.1 -> 1.1 | B14: {=($Z$5-INDEX('Annualized Costs'!$B$5:$E$5,1,$Z$3)+INDEX('Annualized Costs'!$B$5:$E$5,1,$Z$3)*A14)/$Z$4} -> 21.813506 | C14: =B14-$B$4 -> 0.70843356 | D14: =$B$3 -> Case 1 | F14: =F13+0.1 -> 1.1 | G14: {=($Z$5-INDEX('Annualized Costs'!$B$4:$E$4,1,$Z$3)+INDEX('Annualized Costs'!$B$4:$E$4,1,$Z$3)*F14)/$Z$4} -> 21.740718 | H14: =G14-$B$4 -> 0.63564506 | I14: =$B$3 -> Case 1 | K14: 61 | L14: =($Z$5-$Z$8+$Z$8*(K14/'Economic Assumptions'!$D$29))/'OAT Scenario Curves'!$Z$4 -> 21.440018 | M14: =L14-$B$4 -> 0.33494514 | N14: =$B$3 -> Case 1 | P14: =P13*1.1 -> 0.066 | Q14: =($Z$5-INDEX('Annualized Costs'!$B$4:$E$4,1,$Z$3)-INDEX('Annualized Costs'!$B$5:$E$5,1,$Z$3)-INDEX('Annualized Costs'!$B$6:$E$6,1,$Z$3)-INDEX('Annualized Costs'!$B$9:$E$9,1,$Z$3)-INDEX('Annualized Costs'!$B$10:$E$10,1,$Z$3)+INDEX('Annualized Costs'!$B$4:$E$4,1,$Z$3)*((P14*(1+P14)^'Economic Assumptions'!$D$8/((1+P14)^'Economic Assumptions'!$D$8-1))/('Economic Assumptions'!$D$4*(1+'Economic Assumptions'!$D$4)^'Economic Assumptions'!$D$8/((1+'Economic Assumptions'!$D$4)^'Economic Assumptions'!$D$8-1)))+INDEX('Annualized Costs'!$B$5:$E$5,1,$Z$3)*((P14*(1+P14)^'Economic Assumptions'!$D$14/((1+P14)^'Economic Assumptions'!$D$14-1))/('Economic Assumptions'!$D$4*(1+'Economic Assumptions'!$D$4)^'Economic Assumptions'!$D$14/((1+'Economic Assumptions'!$D$4)^'Economic Assumptions'!$D$14-1)))+INDEX('Annualized Costs'!$B$6:$E$6,1,$Z$3)*((P14*(1+P14)^'Economic Assumptions'!$D$20/((1+P14)^'Economic Assumptions'!$D$20-1))/('Economic Assumptions'!$D$4*(1+'Economic Assumptions'!$D$4)^'Economic Assumptions'!$D$20/((1+'Economic Assumptions'!$D$4)^'Economic Assumptions'!$D$20-1)))+(INDEX('Annualized Costs'!$B$9:$E$9,1,$Z$3)+INDEX('Annualized Costs'!$B$10:$E$10,1,$Z$3))*((P14*(1+P14)^'Economic Assumptions'!$D$25/((1+P14)^'Economic Assumptions'!$D$25-1))/('Economic Assumptions'!$D$4*(1+'Economic Assumptions'!$D$4)^'Economic Assumptions'!$D$25/((1+'Economic Assumptions'!$D$4)^'Economic Assumptions'!$D$25-1))))/$Z$4 -> 21.861319 | R14: =Q14-$B$4 -> 0.75624602 | S14: =$B$3 -> Case 1 | U14: =U13+0.1 -> 1.1 | V14: =($Z$5-$Z$6+$Z$6*U14)/$Z$4 -> 21.487157 | W14: =V14-$B$4 -> 0.38208424 | X14: =$B$3 -> Case 1
A15: =A14+0.1 -> 1.2 | B15: {=($Z$5-INDEX('Annualized Costs'!$B$5:$E$5,1,$Z$3)+INDEX('Annualized Costs'!$B$5:$E$5,1,$Z$3)*A15)/$Z$4} -> 22.52194 | C15: =B15-$B$4 -> 1.4168671 | D15: =$B$3 -> Case 1 | F15: =F14+0.1 -> 1.2 | G15: {=($Z$5-INDEX('Annualized Costs'!$B$4:$E$4,1,$Z$3)+INDEX('Annualized Costs'!$B$4:$E$4,1,$Z$3)*F15)/$Z$4} -> 22.376363 | H15: =G15-$B$4 -> 1.2712901 | I15: =$B$3 -> Case 1 | P15: =P13*1.2 -> 0.072 | Q15: =($Z$5-INDEX('Annualized Costs'!$B$4:$E$4,1,$Z$3)-INDEX('Annualized Costs'!$B$5:$E$5,1,$Z$3)-INDEX('Annualized Costs'!$B$6:$E$6,1,$Z$3)-INDEX('Annualized Costs'!$B$9:$E$9,1,$Z$3)-INDEX('Annualized Costs'!$B$10:$E$10,1,$Z$3)+INDEX('Annualized Costs'!$B$4:$E$4,1,$Z$3)*((P15*(1+P15)^'Economic Assumptions'!$D$8/((1+P15)^'Economic Assumptions'!$D$8-1))/('Economic Assumptions'!$D$4*(1+'Economic Assumptions'!$D$4)^'Economic Assumptions'!$D$8/((1+'Economic Assumptions'!$D$4)^'Economic Assumptions'!$D$8-1)))+INDEX('Annualized Costs'!$B$5:$E$5,1,$Z$3)*((P15*(1+P15)^'Economic Assumptions'!$D$14/((1+P15)^'Economic Assumptions'!$D$14-1))/('Economic Assumptions'!$D$4*(1+'Economic Assumptions'!$D$4)^'Economic Assumptions'!$D$14/((1+'Economic Assumptions'!$D$4)^'Economic Assumptions'!$D$14-1)))+INDEX('Annualized Costs'!$B$6:$E$6,1,$Z$3)*((P15*(1+P15)^'Economic Assumptions'!$D$20/((1+P15)^'Economic Assumptions'!$D$20-1))/('Economic Assumptions'!$D$4*(1+'Economic Assumptions'!$D$4)^'Economic Assumptions'!$D$20/((1+'Economic Assumptions'!$D$4)^'Economic Assumptions'!$D$20-1)))+(INDEX('Annualized Costs'!$B$9:$E$9,1,$Z$3)+INDEX('Annualized Costs'!$B$10:$E$10,1,$Z$3))*((P15*(1+P15)^'Economic Assumptions'!$D$25/((1+P15)^'Economic Assumptions'!$D$25-1))/('Economic Assumptions'!$D$4*(1+'Economic Assumptions'!$D$4)^'Economic Assumptions'!$D$25/((1+'Economic Assumptions'!$D$4)^'Economic Assumptions'!$D$25-1))))/$Z$4 -> 22.634579 | R15: =Q15-$B$4 -> 1.5295058 | S15: =$B$3 -> Case 1 | U15: =U14+0.1 -> 1.2 | V15: =($Z$5-$Z$6+$Z$6*U15)/$Z$4 -> 21.869241 | W15: =V15-$B$4 -> 0.76416847 | X15: =$B$3 -> Case 1
A16: =A15+0.1 -> 1.3 | B16: {=($Z$5-INDEX('Annualized Costs'!$B$5:$E$5,1,$Z$3)+INDEX('Annualized Costs'!$B$5:$E$5,1,$Z$3)*A16)/$Z$4} -> 23.230374 | C16: =B16-$B$4 -> 2.1253007 | D16: =$B$3 -> Case 1 | F16: =F15+0.1 -> 1.3 | G16: {=($Z$5-INDEX('Annualized Costs'!$B$4:$E$4,1,$Z$3)+INDEX('Annualized Costs'!$B$4:$E$4,1,$Z$3)*F16)/$Z$4} -> 23.012008 | H16: =G16-$B$4 -> 1.9069352 | I16: =$B$3 -> Case 1 | P16: =P13*1.3 -> 0.078 | Q16: =($Z$5-INDEX('Annualized Costs'!$B$4:$E$4,1,$Z$3)-INDEX('Annualized Costs'!$B$5:$E$5,1,$Z$3)-INDEX('Annualized Costs'!$B$6:$E$6,1,$Z$3)-INDEX('Annualized Costs'!$B$9:$E$9,1,$Z$3)-INDEX('Annualized Costs'!$B$10:$E$10,1,$Z$3)+INDEX('Annualized Costs'!$B$4:$E$4,1,$Z$3)*((P16*(1+P16)^'Economic Assumptions'!$D$8/((1+P16)^'Economic Assumptions'!$D$8-1))/('Economic Assumptions'!$D$4*(1+'Economic Assumptions'!$D$4)^'Economic Assumptions'!$D$8/((1+'Economic Assumptions'!$D$4)^'Economic Assumptions'!$D$8-1)))+INDEX('Annualized Costs'!$B$5:$E$5,1,$Z$3)*((P16*(1+P16)^'Economic Assumptions'!$D$14/((1+P16)^'Economic Assumptions'!$D$14-1))/('Economic Assumptions'!$D$4*(1+'Economic Assumptions'!$D$4)^'Economic Assumptions'!$D$14/((1+'Economic Assumptions'!$D$4)^'Economic Assumptions'!$D$14-1)))+INDEX('Annualized Costs'!$B$6:$E$6,1,$Z$3)*((P16*(1+P16)^'Economic Assumptions'!$D$20/((1+P16)^'Economic Assumptions'!$D$20-1))/('Economic Assumptions'!$D$4*(1+'Economic Assumptions'!$D$4)^'Economic Assumptions'!$D$20/((1+'Economic Assumptions'!$D$4)^'Economic Assumptions'!$D$20-1)))+(INDEX('Annualized Costs'!$B$9:$E$9,1,$Z$3)+INDEX('Annualized Costs'!$B$10:$E$10,1,$Z$3))*((P16*(1+P16)^'Economic Assumptions'!$D$25/((1+P16)^'Economic Assumptions'!$D$25-1))/('Economic Assumptions'!$D$4*(1+'Economic Assumptions'!$D$4)^'Economic Assumptions'!$D$25/((1+'Economic Assumptions'!$D$4)^'Economic Assumptions'!$D$25-1))))/$Z$4 -> 23.424101 | R16: =Q16-$B$4 -> 2.3190277 | S16: =$B$3 -> Case 1 | U16: =U15+0.1 -> 1.3 | V16: =($Z$5-$Z$6+$Z$6*U16)/$Z$4 -> 22.251326 | W16: =V16-$B$4 -> 1.1462527 | X16: =$B$3 -> Case 1
A17: =A16+0.1 -> 1.4 | B17: {=($Z$5-INDEX('Annualized Costs'!$B$5:$E$5,1,$Z$3)+INDEX('Annualized Costs'!$B$5:$E$5,1,$Z$3)*A17)/$Z$4} -> 23.938807 | C17: =B17-$B$4 -> 2.8337342 | D17: =$B$3 -> Case 1 | F17: =F16+0.1 -> 1.4 | G17: {=($Z$5-INDEX('Annualized Costs'!$B$4:$E$4,1,$Z$3)+INDEX('Annualized Costs'!$B$4:$E$4,1,$Z$3)*F17)/$Z$4} -> 23.647653 | H17: =G17-$B$4 -> 2.5425802 | I17: =$B$3 -> Case 1 | P17: =P13*1.4 -> 0.084 | Q17: =($Z$5-INDEX('Annualized Costs'!$B$4:$E$4,1,$Z$3)-INDEX('Annualized Costs'!$B$5:$E$5,1,$Z$3)-INDEX('Annualized Costs'!$B$6:$E$6,1,$Z$3)-INDEX('Annualized Costs'!$B$9:$E$9,1,$Z$3)-INDEX('Annualized Costs'!$B$10:$E$10,1,$Z$3)+INDEX('Annualized Costs'!$B$4:$E$4,1,$Z$3)*((P17*(1+P17)^'Economic Assumptions'!$D$8/((1+P17)^'Economic Assumptions'!$D$8-1))/('Economic Assumptions'!$D$4*(1+'Economic Assumptions'!$D$4)^'Economic Assumptions'!$D$8/((1+'Economic Assumptions'!$D$4)^'Economic Assumptions'!$D$8-1)))+INDEX('Annualized Costs'!$B$5:$E$5,1,$Z$3)*((P17*(1+P17)^'Economic Assumptions'!$D$14/((1+P17)^'Economic Assumptions'!$D$14-1))/('Economic Assumptions'!$D$4*(1+'Economic Assumptions'!$D$4)^'Economic Assumptions'!$D$14/((1+'Economic Assumptions'!$D$4)^'Economic Assumptions'!$D$14-1)))+INDEX('Annualized Costs'!$B$6:$E$6,1,$Z$3)*((P17*(1+P17)^'Economic Assumptions'!$D$20/((1+P17)^'Economic Assumptions'!$D$20-1))/('Economic Assumptions'!$D$4*(1+'Economic Assumptions'!$D$4)^'Economic Assumptions'!$D$20/((1+'Economic Assumptions'!$D$4)^'Economic Assumptions'!$D$20-1)))+(INDEX('Annualized Costs'!$B$9:$E$9,1,$Z$3)+INDEX('Annualized Costs'!$B$10:$E$10,1,$Z$3))*((P17*(1+P17)^'Economic Assumptions'!$D$25/((1+P17)^'Economic Assumptions'!$D$25-1))/('Economic Assumptions'!$D$4*(1+'Economic Assumptions'!$D$4)^'Economic Assumptions'!$D$25/((1+'Economic Assumptions'!$D$4)^'Economic Assumptions'!$D$25-1))))/$Z$4 -> 24.229128 | R17: =Q17-$B$4 -> 3.1240553 | S17: =$B$3 -> Case 1 | U17: =U16+0.1 -> 1.4 | V17: =($Z$5-$Z$6+$Z$6*U17)/$Z$4 -> 22.63341 | W17: =V17-$B$4 -> 1.5283369 | X17: =$B$3 -> Case 1
A18: =A17+0.1 -> 1.5 | B18: {=($Z$5-INDEX('Annualized Costs'!$B$5:$E$5,1,$Z$3)+INDEX('Annualized Costs'!$B$5:$E$5,1,$Z$3)*A18)/$Z$4} -> 24.647241 | C18: =B18-$B$4 -> 3.5421678 | D18: =$B$3 -> Case 1 | F18: =F17+0.1 -> 1.5 | G18: {=($Z$5-INDEX('Annualized Costs'!$B$4:$E$4,1,$Z$3)+INDEX('Annualized Costs'!$B$4:$E$4,1,$Z$3)*F18)/$Z$4} -> 24.283298 | H18: =G18-$B$4 -> 3.1782253 | I18: =$B$3 -> Case 1 | P18: =P13*1.5 -> 0.09 | Q18: =($Z$5-INDEX('Annualized Costs'!$B$4:$E$4,1,$Z$3)-INDEX('Annualized Costs'!$B$5:$E$5,1,$Z$3)-INDEX('Annualized Costs'!$B$6:$E$6,1,$Z$3)-INDEX('Annualized Costs'!$B$9:$E$9,1,$Z$3)-INDEX('Annualized Costs'!$B$10:$E$10,1,$Z$3)+INDEX('Annualized Costs'!$B$4:$E$4,1,$Z$3)*((P18*(1+P18)^'Economic Assumptions'!$D$8/((1+P18)^'Economic Assumptions'!$D$8-1))/('Economic Assumptions'!$D$4*(1+'Economic Assumptions'!$D$4)^'Economic Assumptions'!$D$8/((1+'Economic Assumptions'!$D$4)^'Economic Assumptions'!$D$8-1)))+INDEX('Annualized Costs'!$B$5:$E$5,1,$Z$3)*((P18*(1+P18)^'Economic Assumptions'!$D$14/((1+P18)^'Economic Assumptions'!$D$14-1))/('Economic Assumptions'!$D$4*(1+'Economic Assumptions'!$D$4)^'Economic Assumptions'!$D$14/((1+'Economic Assumptions'!$D$4)^'Economic Assumptions'!$D$14-1)))+INDEX('Annualized Costs'!$B$6:$E$6,1,$Z$3)*((P18*(1+P18)^'Economic Assumptions'!$D$20/((1+P18)^'Economic Assumptions'!$D$20-1))/('Economic Assumptions'!$D$4*(1+'Economic Assumptions'!$D$4)^'Economic Assumptions'!$D$20/((1+'Economic Assumptions'!$D$4)^'Economic Assumptions'!$D$20-1)))+(INDEX('Annualized Costs'!$B$9:$E$9,1,$Z$3)+INDEX('Annualized Costs'!$B$10:$E$10,1,$Z$3))*((P18*(1+P18)^'Economic Assumptions'!$D$25/((1+P18)^'Economic Assumptions'!$D$25-1))/('Economic Assumptions'!$D$4*(1+'Economic Assumptions'!$D$4)^'Economic Assumptions'!$D$25/((1+'Economic Assumptions'!$D$4)^'Economic Assumptions'!$D$25-1))))/$Z$4 -> 25.048905 | R18: =Q18-$B$4 -> 3.9438326 | S18: =$B$3 -> Case 1 | U18: =U17+0.1 -> 1.5 | V18: =($Z$5-$Z$6+$Z$6*U18)/$Z$4 -> 23.015494 | W18: =V18-$B$4 -> 1.9104212 | X18: =$B$3 -> Case 1
J30: System economics is not highly sensitive to electrolyzer efficiency.
U37: At 50% reduction in electricity cost, LCOH reduces by 1.9eur/kg.
A38: Electrolyzer CAPEX infuence is higher and linear | U38: Electricity price has stronger influence on LCOH than SEC.
U40: But not all the time.
U41: If electricity becomes expensive, electrolyzer can operate differently looking at the price hour, PV utilization could change, storage usage could change (we can opt for more storage than required). This will ultimately make grid cost vs LCOH non- linear
F42: Case | G42: Factor | H42: PV CAPEX | I42: Electrolyzer CAPEX | J42: Grid Cost | K42: Discount Rate
F43: =$B$3 -> Case 1 | G43: 0.5 | H43: =G8 -> 17.926848 | I43: =B8 -> 17.562905 | J43: =V8 -> 19.194652 | K43: =Q8 -> 17.604199
F44: =$B$3 -> Case 1 | G44: =G43+0.1 -> 0.6 | H44: =G9 -> 18.562493 | I44: =B9 -> 18.271339 | J44: =V9 -> 19.576736 | K44: =Q9 -> 18.264728
F45: =$B$3 -> Case 1 | G45: =G44+0.1 -> 0.7 | H45: =G10 -> 19.198138 | I45: =B10 -> 18.979772 | J45: =V10 -> 19.95882 | K45: =Q10 -> 18.945726
F46: =$B$3 -> Case 1 | G46: =G45+0.1 -> 0.8 | H46: =G11 -> 19.833783 | I46: =B11 -> 19.688206 | J46: =V11 -> 20.340904 | K46: =Q11 -> 19.646566
F47: =$B$3 -> Case 1 | G47: =G46+0.1 -> 0.9 | H47: =G12 -> 20.469428 | I47: =B12 -> 20.396639 | J47: =V12 -> 20.722989 | K47: =Q12 -> 20.366581
F48: =$B$3 -> Case 1 | G48: =G47+0.1 -> 1 | H48: =G13 -> 21.105073 | I48: =B13 -> 21.105073 | J48: =V13 -> 21.105073 | K48: =Q13 -> 21.105073
F49: =$B$3 -> Case 1 | G49: =G48+0.1 -> 1.1 | H49: =G14 -> 21.740718 | I49: =B14 -> 21.813506 | J49: =V14 -> 21.487157 | K49: =Q14 -> 21.861319
F50: =$B$3 -> Case 1 | G50: =G49+0.1 -> 1.2 | H50: =G15 -> 22.376363 | I50: =B15 -> 22.52194 | J50: =V15 -> 21.869241 | K50: =Q15 -> 22.634579
F51: =$B$3 -> Case 1 | G51: =G50+0.1 -> 1.3 | H51: =G16 -> 23.012008 | I51: =B16 -> 23.230374 | J51: =V16 -> 22.251326 | K51: =Q16 -> 23.424101
F52: =$B$3 -> Case 1 | G52: =G51+0.1 -> 1.4 | H52: =G17 -> 23.647653 | I52: =B17 -> 23.938807 | J52: =V17 -> 22.63341 | K52: =Q17 -> 24.229128
F53: =$B$3 -> Case 1 | G53: =G52+0.1 -> 1.5 | H53: =G18 -> 24.283298 | I53: =B18 -> 24.647241 | J53: =V18 -> 23.015494 | K53: =Q18 -> 25.048905

Sheet Two-parameters sensitivity
A1: Two-Way LCOH Sensitivity Analysis
A3: METHOD | C3: Two-parameter (bivariate) sensitivity | I3: Case idx | J3: =MATCH($C$4, 'LCOH '!$B$3:'LCOH '!$E$3,0) -> 1
A4: Selected case | C4: Case 1 | I4: Annual H2 (Kg) | J4: {=INDEX('Case Inputs'!$C$6:$F$6,1,'OAT Scenario Curves'!$Z$3)} -> 738.4
A5: Base LCOH (€/kg) | C5: =INDEX('LCOH '!$B$15:$E$15,1,MATCH($C$4,'LCOH '!$B$3:$E$3,0)) -> 21.105073 | I5: Base net annual system cost | J5: {=INDEX('Annualized Costs'!$B$22:'Annualized Costs'!$E$22,1,'Two-parameters sensitivity'!$J$3)} -> 15583.986
I6: ELY-sensitive annual cost (€/yr) | J6: =SUM(INDEX('Annualized Costs'!$B$5:$E$5,1,$J$3),INDEX('Annualized Costs'!$B$12:$E$12,1,$J$3),INDEX('Annualized Costs'!$B$16:$E$16,1,$J$3)) -> 7455.9726
A7: Electrolyzer CAPEX × Storage Cost — LCOH Matrix (€/kg H₂) | I7: Storage-sensitive annual cost (€/yr) | J7: =SUM(INDEX('Annualized Costs'!$B$9:$E$9,1,$J$3),INDEX('Annualized Costs'!$B$10:$E$10,1,$J$3),INDEX('Annualized Costs'!$B$14:$E$14,1,$J$3)) -> 676.40452
A8: ELY CAPEX ↓ / Storage cost → | B8: 0.5 | C8: 0.6 | D8: 0.8 | E8: 1 | F8: 1.2 | G8: 1.4 | H8: 1.5 | I8: Base net LCOH | J8: =$J$5/$J$4 -> 21.105073
A9: 0.5 | B9: =($J$5-$J$6-$J$7+$J$6*$A9+$J$7*B$8)/$J$4 -> 15.598317 | C9: =($J$5-$J$6-$J$7+$J$6*$A9+$J$7*C$8)/$J$4 -> 15.689921 | D9: =($J$5-$J$6-$J$7+$J$6*$A9+$J$7*D$8)/$J$4 -> 15.873129 | E9: =($J$5-$J$6-$J$7+$J$6*$A9+$J$7*E$8)/$J$4 -> 16.056337 | F9: =($J$5-$J$6-$J$7+$J$6*$A9+$J$7*F$8)/$J$4 -> 16.239546 | G9: =($J$5-$J$6-$J$7+$J$6*$A9+$J$7*G$8)/$J$4 -> 16.422754 | H9: =($J$5-$J$6-$J$7+$J$6*$A9+$J$7*H$8)/$J$4 -> 16.514358
A10: 0.6 | B10: =($J$5-$J$6-$J$7+$J$6*$A10+$J$7*B$8)/$J$4 -> 16.608064 | C10: =($J$5-$J$6-$J$7+$J$6*$A10+$J$7*C$8)/$J$4 -> 16.699668 | D10: =($J$5-$J$6-$J$7+$J$6*$A10+$J$7*D$8)/$J$4 -> 16.882876 | E10: =($J$5-$J$6-$J$7+$J$6*$A10+$J$7*E$8)/$J$4 -> 17.066084 | F10: =($J$5-$J$6-$J$7+$J$6*$A10+$J$7*F$8)/$J$4 -> 17.249293 | G10: =($J$5-$J$6-$J$7+$J$6*$A10+$J$7*G$8)/$J$4 -> 17.432501 | H10: =($J$5-$J$6-$J$7+$J$6*$A10+$J$7*H$8)/$J$4 -> 17.524105
A11: 0.8 | B11: =($J$5-$J$6-$J$7+$J$6*$A11+$J$7*B$8)/$J$4 -> 18.627558 | C11: =($J$5-$J$6-$J$7+$J$6*$A11+$J$7*C$8)/$J$4 -> 18.719162 | D11: =($J$5-$J$6-$J$7+$J$6*$A11+$J$7*D$8)/$J$4 -> 18.902371 | E11: =($J$5-$J$6-$J$7+$J$6*$A11+$J$7*E$8)/$J$4 -> 19.085579 | F11: =($J$5-$J$6-$J$7+$J$6*$A11+$J$7*F$8)/$J$4 -> 19.268787 | G11: =($J$5-$J$6-$J$7+$J$6*$A11+$J$7*G$8)/$J$4 -> 19.451995 | H11: =($J$5-$J$6-$J$7+$J$6*$A11+$J$7*H$8)/$J$4 -> 19.543599
A12: 1 | B12: =($J$5-$J$6-$J$7+$J$6*$A12+$J$7*B$8)/$J$4 -> 20.647052 | C12: =($J$5-$J$6-$J$7+$J$6*$A12+$J$7*C$8)/$J$4 -> 20.738657 | D12: =($J$5-$J$6-$J$7+$J$6*$A12+$J$7*D$8)/$J$4 -> 20.921865 | E12: =($J$5-$J$6-$J$7+$J$6*$A12+$J$7*E$8)/$J$4 -> 21.105073 | F12: =($J$5-$J$6-$J$7+$J$6*$A12+$J$7*F$8)/$J$4 -> 21.288281 | G12: =($J$5-$J$6-$J$7+$J$6*$A12+$J$7*G$8)/$J$4 -> 21.471489 | H12: =($J$5-$J$6-$J$7+$J$6*$A12+$J$7*H$8)/$J$4 -> 21.563093
A13: 1.2 | B13: =($J$5-$J$6-$J$7+$J$6*$A13+$J$7*B$8)/$J$4 -> 22.666547 | C13: =($J$5-$J$6-$J$7+$J$6*$A13+$J$7*C$8)/$J$4 -> 22.758151 | D13: =($J$5-$J$6-$J$7+$J$6*$A13+$J$7*D$8)/$J$4 -> 22.941359 | E13: =($J$5-$J$6-$J$7+$J$6*$A13+$J$7*E$8)/$J$4 -> 23.124567 | F13: =($J$5-$J$6-$J$7+$J$6*$A13+$J$7*F$8)/$J$4 -> 23.307775 | G13: =($J$5-$J$6-$J$7+$J$6*$A13+$J$7*G$8)/$J$4 -> 23.490983 | H13: =($J$5-$J$6-$J$7+$J$6*$A13+$J$7*H$8)/$J$4 -> 23.582587
A14: 1.4 | B14: =($J$5-$J$6-$J$7+$J$6*$A14+$J$7*B$8)/$J$4 -> 24.686041 | C14: =($J$5-$J$6-$J$7+$J$6*$A14+$J$7*C$8)/$J$4 -> 24.777645 | D14: =($J$5-$J$6-$J$7+$J$6*$A14+$J$7*D$8)/$J$4 -> 24.960853 | E14: =($J$5-$J$6-$J$7+$J$6*$A14+$J$7*E$8)/$J$4 -> 25.144061 | F14: =($J$5-$J$6-$J$7+$J$6*$A14+$J$7*F$8)/$J$4 -> 25.327269 | G14: =($J$5-$J$6-$J$7+$J$6*$A14+$J$7*G$8)/$J$4 -> 25.510478 | H14: =($J$5-$J$6-$J$7+$J$6*$A14+$J$7*H$8)/$J$4 -> 25.602082
